[2024-10-23T11:11:04.347+0000] {local_task_job_runner.py:120} INFO - ::group::Pre task execution logs
[2024-10-23T11:11:04.438+0000] {taskinstance.py:2076} INFO - Dependencies all met for dep_context=non-requeueable deps ti=<TaskInstance: user_automation.stream_data_from_api scheduled__2024-10-22T00:00:00+00:00 [queued]>
[2024-10-23T11:11:04.458+0000] {taskinstance.py:2076} INFO - Dependencies all met for dep_context=requeueable deps ti=<TaskInstance: user_automation.stream_data_from_api scheduled__2024-10-22T00:00:00+00:00 [queued]>
[2024-10-23T11:11:04.460+0000] {taskinstance.py:2306} INFO - Starting attempt 5 of 4
[2024-10-23T11:11:04.539+0000] {taskinstance.py:2330} INFO - Executing <Task(PythonOperator): stream_data_from_api> on 2024-10-22 00:00:00+00:00
[2024-10-23T11:11:04.585+0000] {standard_task_runner.py:90} INFO - Running: ['***', 'tasks', 'run', 'user_automation', 'stream_data_from_api', 'scheduled__2024-10-22T00:00:00+00:00', '--job-id', '112', '--raw', '--subdir', 'DAGS_FOLDER/kafka_stream.py', '--cfg-path', '/tmp/tmpja9v99xe']
[2024-10-23T11:11:04.598+0000] {standard_task_runner.py:91} INFO - Job 112: Subtask stream_data_from_api
[2024-10-23T11:11:04.603+0000] {logging_mixin.py:188} WARNING - /home/***/.local/lib/python3.12/site-packages/***/task/task_runner/standard_task_runner.py:62 DeprecationWarning: This process (pid=217) is multi-threaded, use of fork() may lead to deadlocks in the child.
[2024-10-23T11:11:04.605+0000] {standard_task_runner.py:64} INFO - Started process 220 to run task
[2024-10-23T11:11:04.782+0000] {task_command.py:426} INFO - Running <TaskInstance: user_automation.stream_data_from_api scheduled__2024-10-22T00:00:00+00:00 [running]> on host bdd5421c2cdf
[2024-10-23T11:11:05.224+0000] {taskinstance.py:2648} INFO - Exporting env vars: AIRFLOW_CTX_DAG_OWNER='admin' AIRFLOW_CTX_DAG_ID='user_automation' AIRFLOW_CTX_TASK_ID='stream_data_from_api' AIRFLOW_CTX_EXECUTION_DATE='2024-10-22T00:00:00+00:00' AIRFLOW_CTX_TRY_NUMBER='5' AIRFLOW_CTX_DAG_RUN_ID='scheduled__2024-10-22T00:00:00+00:00'
[2024-10-23T11:11:05.230+0000] {taskinstance.py:430} INFO - ::endgroup::
[2024-10-23T11:11:05.918+0000] {conn.py:362} INFO - <BrokerConnection node_id=bootstrap-0 host=broker:9093 <connecting> [IPv4 ('172.21.0.3', 9093)]>: connecting to broker:9093 [('172.21.0.3', 9093) IPv4]
[2024-10-23T11:11:05.922+0000] {conn.py:957} INFO - Probing node bootstrap-0 broker version
[2024-10-23T11:11:05.929+0000] {conn.py:393} INFO - <BrokerConnection node_id=bootstrap-0 host=broker:9093 <connecting> [IPv4 ('172.21.0.3', 9093)]>: Connection complete.
[2024-10-23T11:11:06.071+0000] {conn.py:1019} INFO - Broker version identified as 2.6.0
[2024-10-23T11:11:06.075+0000] {conn.py:1020} INFO - Set configuration api_version=(2, 6, 0) to skip auto check_version requests on startup
[2024-10-23T11:11:07.472+0000] {conn.py:362} INFO - <BrokerConnection node_id=1002 host=broker:9093 <connecting> [IPv4 ('172.21.0.3', 9093)]>: connecting to broker:9093 [('172.21.0.3', 9093) IPv4]
[2024-10-23T11:11:07.475+0000] {conn.py:393} INFO - <BrokerConnection node_id=1002 host=broker:9093 <connecting> [IPv4 ('172.21.0.3', 9093)]>: Connection complete.
[2024-10-23T11:11:07.481+0000] {conn.py:673} INFO - <BrokerConnection node_id=bootstrap-0 host=broker:9093 <connected> [IPv4 ('172.21.0.3', 9093)]>: Closing connection. 
[2024-10-23T11:11:37.934+0000] {record_accumulator.py:71} WARNING - Produced messages to topic-partition ('users_created', 2) with base offset -1 log start offset None and error None.
[2024-10-23T11:11:33.168+0000] {job.py:218} ERROR - Job heartbeat got an exception
Traceback (most recent call last):
  File "/home/airflow/.local/lib/python3.12/site-packages/sqlalchemy/engine/base.py", line 3371, in _wrap_pool_connect
    return fn()
           ^^^^
  File "/home/airflow/.local/lib/python3.12/site-packages/sqlalchemy/pool/base.py", line 327, in connect
    return _ConnectionFairy._checkout(self)
           ^^^^^^^^^^^^^^^^^^^^^^^^^^^^^^^^
  File "/home/airflow/.local/lib/python3.12/site-packages/sqlalchemy/pool/base.py", line 894, in _checkout
    fairy = _ConnectionRecord.checkout(pool)
            ^^^^^^^^^^^^^^^^^^^^^^^^^^^^^^^^
  File "/home/airflow/.local/lib/python3.12/site-packages/sqlalchemy/pool/base.py", line 493, in checkout
    rec = pool._do_get()
          ^^^^^^^^^^^^^^
  File "/home/airflow/.local/lib/python3.12/site-packages/sqlalchemy/pool/impl.py", line 256, in _do_get
    return self._create_connection()
           ^^^^^^^^^^^^^^^^^^^^^^^^^
  File "/home/airflow/.local/lib/python3.12/site-packages/sqlalchemy/pool/base.py", line 273, in _create_connection
    return _ConnectionRecord(self)
           ^^^^^^^^^^^^^^^^^^^^^^^
  File "/home/airflow/.local/lib/python3.12/site-packages/sqlalchemy/pool/base.py", line 388, in __init__
    self.__connect()
  File "/home/airflow/.local/lib/python3.12/site-packages/sqlalchemy/pool/base.py", line 690, in __connect
    with util.safe_reraise():
  File "/home/airflow/.local/lib/python3.12/site-packages/sqlalchemy/util/langhelpers.py", line 70, in __exit__
    compat.raise_(
  File "/home/airflow/.local/lib/python3.12/site-packages/sqlalchemy/util/compat.py", line 211, in raise_
    raise exception
  File "/home/airflow/.local/lib/python3.12/site-packages/sqlalchemy/pool/base.py", line 686, in __connect
    self.dbapi_connection = connection = pool._invoke_creator(self)
                                         ^^^^^^^^^^^^^^^^^^^^^^^^^^
  File "/home/airflow/.local/lib/python3.12/site-packages/sqlalchemy/engine/create.py", line 574, in connect
    return dialect.connect(*cargs, **cparams)
           ^^^^^^^^^^^^^^^^^^^^^^^^^^^^^^^^^^
  File "/home/airflow/.local/lib/python3.12/site-packages/sqlalchemy/engine/default.py", line 598, in connect
    return self.dbapi.connect(*cargs, **cparams)
           ^^^^^^^^^^^^^^^^^^^^^^^^^^^^^^^^^^^^^
  File "/home/airflow/.local/lib/python3.12/site-packages/psycopg2/__init__.py", line 122, in connect
    conn = _connect(dsn, connection_factory=connection_factory, **kwasync)
           ^^^^^^^^^^^^^^^^^^^^^^^^^^^^^^^^^^^^^^^^^^^^^^^^^^^^^^^^^^^^^^^
psycopg2.OperationalError: could not translate host name "postgres" to address: Temporary failure in name resolution


The above exception was the direct cause of the following exception:

Traceback (most recent call last):
  File "/home/airflow/.local/lib/python3.12/site-packages/airflow/jobs/job.py", line 213, in heartbeat
    heartbeat_callback(session)
  File "/home/airflow/.local/lib/python3.12/site-packages/airflow/utils/session.py", line 76, in wrapper
    return func(*args, **kwargs)
           ^^^^^^^^^^^^^^^^^^^^^
  File "/home/airflow/.local/lib/python3.12/site-packages/airflow/jobs/local_task_job_runner.py", line 261, in heartbeat_callback
    self.task_instance.refresh_from_db()
  File "/home/airflow/.local/lib/python3.12/site-packages/airflow/utils/session.py", line 79, in wrapper
    return func(*args, session=session, **kwargs)
           ^^^^^^^^^^^^^^^^^^^^^^^^^^^^^^^^^^^^^^
  File "/home/airflow/.local/lib/python3.12/site-packages/airflow/models/taskinstance.py", line 1821, in refresh_from_db
    _refresh_from_db(task_instance=self, session=session, lock_for_update=lock_for_update)
  File "/home/airflow/.local/lib/python3.12/site-packages/airflow/models/taskinstance.py", line 510, in _refresh_from_db
    ti = TaskInstance.get_task_instance(
         ^^^^^^^^^^^^^^^^^^^^^^^^^^^^^^^
  File "/home/airflow/.local/lib/python3.12/site-packages/airflow/api_internal/internal_api_call.py", line 115, in wrapper
    return func(*args, **kwargs)
           ^^^^^^^^^^^^^^^^^^^^^
  File "/home/airflow/.local/lib/python3.12/site-packages/airflow/utils/session.py", line 76, in wrapper
    return func(*args, **kwargs)
           ^^^^^^^^^^^^^^^^^^^^^
  File "/home/airflow/.local/lib/python3.12/site-packages/airflow/models/taskinstance.py", line 1807, in get_task_instance
    return query.one_or_none()
           ^^^^^^^^^^^^^^^^^^^
  File "/home/airflow/.local/lib/python3.12/site-packages/sqlalchemy/orm/query.py", line 2850, in one_or_none
    return self._iter().one_or_none()
           ^^^^^^^^^^^^
  File "/home/airflow/.local/lib/python3.12/site-packages/sqlalchemy/orm/query.py", line 2916, in _iter
    result = self.session.execute(
             ^^^^^^^^^^^^^^^^^^^^^
  File "/home/airflow/.local/lib/python3.12/site-packages/sqlalchemy/orm/session.py", line 1716, in execute
    conn = self._connection_for_bind(bind)
           ^^^^^^^^^^^^^^^^^^^^^^^^^^^^^^^
  File "/home/airflow/.local/lib/python3.12/site-packages/sqlalchemy/orm/session.py", line 1555, in _connection_for_bind
    return self._transaction._connection_for_bind(
           ^^^^^^^^^^^^^^^^^^^^^^^^^^^^^^^^^^^^^^^
  File "/home/airflow/.local/lib/python3.12/site-packages/sqlalchemy/orm/session.py", line 750, in _connection_for_bind
    conn = bind.connect()
           ^^^^^^^^^^^^^^
  File "/home/airflow/.local/lib/python3.12/site-packages/sqlalchemy/future/engine.py", line 412, in connect
    return super(Engine, self).connect()
           ^^^^^^^^^^^^^^^^^^^^^^^^^^^^^
  File "/home/airflow/.local/lib/python3.12/site-packages/sqlalchemy/engine/base.py", line 3325, in connect
    return self._connection_cls(self, close_with_result=close_with_result)
           ^^^^^^^^^^^^^^^^^^^^^^^^^^^^^^^^^^^^^^^^^^^^^^^^^^^^^^^^^^^^^^^
  File "/home/airflow/.local/lib/python3.12/site-packages/sqlalchemy/engine/base.py", line 96, in __init__
    else engine.raw_connection()
         ^^^^^^^^^^^^^^^^^^^^^^^
  File "/home/airflow/.local/lib/python3.12/site-packages/sqlalchemy/engine/base.py", line 3404, in raw_connection
    return self._wrap_pool_connect(self.pool.connect, _connection)
           ^^^^^^^^^^^^^^^^^^^^^^^^^^^^^^^^^^^^^^^^^^^^^^^^^^^^^^^
  File "/home/airflow/.local/lib/python3.12/site-packages/sqlalchemy/engine/base.py", line 3374, in _wrap_pool_connect
    Connection._handle_dbapi_exception_noconnection(
  File "/home/airflow/.local/lib/python3.12/site-packages/sqlalchemy/engine/base.py", line 2208, in _handle_dbapi_exception_noconnection
    util.raise_(
  File "/home/airflow/.local/lib/python3.12/site-packages/sqlalchemy/util/compat.py", line 211, in raise_
    raise exception
  File "/home/airflow/.local/lib/python3.12/site-packages/sqlalchemy/engine/base.py", line 3371, in _wrap_pool_connect
    return fn()
           ^^^^
  File "/home/airflow/.local/lib/python3.12/site-packages/sqlalchemy/pool/base.py", line 327, in connect
    return _ConnectionFairy._checkout(self)
           ^^^^^^^^^^^^^^^^^^^^^^^^^^^^^^^^
  File "/home/airflow/.local/lib/python3.12/site-packages/sqlalchemy/pool/base.py", line 894, in _checkout
    fairy = _ConnectionRecord.checkout(pool)
            ^^^^^^^^^^^^^^^^^^^^^^^^^^^^^^^^
  File "/home/airflow/.local/lib/python3.12/site-packages/sqlalchemy/pool/base.py", line 493, in checkout
    rec = pool._do_get()
          ^^^^^^^^^^^^^^
  File "/home/airflow/.local/lib/python3.12/site-packages/sqlalchemy/pool/impl.py", line 256, in _do_get
    return self._create_connection()
           ^^^^^^^^^^^^^^^^^^^^^^^^^
  File "/home/airflow/.local/lib/python3.12/site-packages/sqlalchemy/pool/base.py", line 273, in _create_connection
    return _ConnectionRecord(self)
           ^^^^^^^^^^^^^^^^^^^^^^^
  File "/home/airflow/.local/lib/python3.12/site-packages/sqlalchemy/pool/base.py", line 388, in __init__
    self.__connect()
  File "/home/airflow/.local/lib/python3.12/site-packages/sqlalchemy/pool/base.py", line 690, in __connect
    with util.safe_reraise():
  File "/home/airflow/.local/lib/python3.12/site-packages/sqlalchemy/util/langhelpers.py", line 70, in __exit__
    compat.raise_(
  File "/home/airflow/.local/lib/python3.12/site-packages/sqlalchemy/util/compat.py", line 211, in raise_
    raise exception
  File "/home/airflow/.local/lib/python3.12/site-packages/sqlalchemy/pool/base.py", line 686, in __connect
    self.dbapi_connection = connection = pool._invoke_creator(self)
                                         ^^^^^^^^^^^^^^^^^^^^^^^^^^
  File "/home/airflow/.local/lib/python3.12/site-packages/sqlalchemy/engine/create.py", line 574, in connect
    return dialect.connect(*cargs, **cparams)
           ^^^^^^^^^^^^^^^^^^^^^^^^^^^^^^^^^^
  File "/home/airflow/.local/lib/python3.12/site-packages/sqlalchemy/engine/default.py", line 598, in connect
    return self.dbapi.connect(*cargs, **cparams)
           ^^^^^^^^^^^^^^^^^^^^^^^^^^^^^^^^^^^^^
  File "/home/airflow/.local/lib/python3.12/site-packages/psycopg2/__init__.py", line 122, in connect
    conn = _connect(dsn, connection_factory=connection_factory, **kwasync)
           ^^^^^^^^^^^^^^^^^^^^^^^^^^^^^^^^^^^^^^^^^^^^^^^^^^^^^^^^^^^^^^^
sqlalchemy.exc.OperationalError: (psycopg2.OperationalError) could not translate host name "postgres" to address: Temporary failure in name resolution

(Background on this error at: https://sqlalche.me/e/14/e3q8)
[2024-10-23T11:11:38.165+0000] {record_accumulator.py:330} WARNING - Expired 1 batches in accumulator
[2024-10-23T11:11:42.428+0000] {job.py:226} ERROR - Job heartbeat failed with error. Scheduler is in unhealthy state
[2024-10-23T11:11:42.672+0000] {record_accumulator.py:71} WARNING - Produced messages to topic-partition ('users_created', 0) with base offset -1 log start offset None and error None.
[2024-10-23T11:11:42.840+0000] {record_accumulator.py:330} WARNING - Expired 1 batches in accumulator
[2024-10-23T11:12:20.138+0000] {job.py:226} ERROR - Job heartbeat failed with error. Scheduler is in unhealthy state
[2024-10-23T11:14:05.333+0000] {kafka_stream.py:59} ERROR - An error occured: ('Connection aborted.', ConnectionResetError(104, 'Connection reset by peer'))
[2024-10-23T11:14:05.337+0000] {python.py:237} INFO - Done. Returned value was: {'first_name': 'کوروش', 'last_name': 'حیدری', 'gender': 'male', 'address': '6416 استاد قریب, ارومیه, قم, Iran', 'post_code': 20327, 'email': 'khwrwsh.hydry@example.com', 'username': 'silvergoose707', 'dob': '1983-07-06T21:36:55.799Z', 'registered_date': '2003-06-24T12:17:45.417Z', 'phone': '073-63237523', 'picture': 'https://randomuser.me/api/portraits/med/men/60.jpg'}
[2024-10-23T11:14:05.346+0000] {taskinstance.py:441} INFO - ::group::Post task execution logs
[2024-10-23T11:14:06.459+0000] {conn.py:673} INFO - <BrokerConnection node_id=1002 host=broker:9093 <connected> [IPv4 ('172.21.0.3', 9093)]>: Closing connection. 
[2024-10-23T11:14:06.460+0000] {client_async.py:939} WARNING - Unable to send to wakeup socket!
[2024-10-23T11:14:06.490+0000] {taskinstance.py:1206} INFO - Marking task as SUCCESS. dag_id=user_automation, task_id=stream_data_from_api, run_id=scheduled__2024-10-22T00:00:00+00:00, execution_date=20241022T000000, start_date=20241023T111104, end_date=20241023T111406
[2024-10-23T11:14:06.595+0000] {local_task_job_runner.py:243} INFO - Task exited with return code 0
[2024-10-23T11:14:06.650+0000] {taskinstance.py:3503} INFO - 0 downstream tasks scheduled from follow-on schedule check
[2024-10-23T11:14:06.665+0000] {local_task_job_runner.py:222} INFO - ::endgroup::
